<?xml version="1.0" ?>
<robot name="export_2">
  <link name="Main_body_Frame_1">
    <visual name="Main_body_Frame_1_visual">
      <origin xyz="0 0 0" rpy="0 0 0"/>
      <geometry>
        <mesh filename="../custom_meshes/Main_body_Frame_1.stl"/>
      </geometry>
      <material name="Main_body_Frame_1_material">
        <color rgba="0 1 1 1"/>
      </material>
    </visual>
    <collision name="Main_body_Frame_1_collision">
      <origin xyz="0 0 0" rpy="0 0 0"/>
      <geometry>
        <mesh filename="../custom_meshes/Main_body_Frame_1.stl"/>
      </geometry>
    </collision>
    <inertial>
      <mass value="0"/>
      <inertia ixx="0" iyy="0" izz="0" ixy="0" ixz="0" iyz="0"/>
      <origin xyz="0.057029 0.36776784 -0.6147399" rpy="0 0 0"/>
    </inertial>
  </link>
  <link name="Front_Right_Side_Motor_Cap_1">
    <visual name="Front_Right_Side_Motor_Cap_1_visual">
      <origin xyz="0 0 0" rpy="0 0 0"/>
      <geometry>
        <mesh filename="../custom_meshes/Front_Right_Side_Motor_Cap_1.stl"/>
      </geometry>
      <material name="Front_Right_Side_Motor_Cap_1_material">
        <color rgba="0 0 0 1"/>
      </material>
    </visual>
    <collision name="Front_Right_Side_Motor_Cap_1_collision">
      <origin xyz="0 0 0" rpy="0 0 0"/>
      <geometry>
        <mesh filename="../custom_meshes/Front_Right_Side_Motor_Cap_1.stl"/>
      </geometry>
    </collision>
    <inertial>
      <mass value="0"/>
      <inertia ixx="0" iyy="0" izz="0" ixy="0" ixz="0" iyz="0"/>
      <origin xyz="0.29 0 -0.17" rpy="0 0 0"/>
    </inertial>
  </link>
  <link name="Front_Left_Side_Motor_Cap_1">
    <visual name="Front_Left_Side_Motor_Cap_1_visual">
      <origin xyz="0 0 0" rpy="0 0 0"/>
      <geometry>
        <mesh filename="../custom_meshes/Front_Left_Side_Motor_Cap_1.stl"/>
      </geometry>
      <material name="Front_Left_Side_Motor_Cap_1_material">
        <color rgba="1 1 1 1"/>
      </material>
    </visual>
    <collision name="Front_Left_Side_Motor_Cap_1_collision">
      <origin xyz="0 0 0" rpy="0 0 0"/>
      <geometry>
        <mesh filename="../custom_meshes/Front_Left_Side_Motor_Cap_1.stl"/>
      </geometry>
    </collision>
    <inertial>
      <mass value="0"/>
      <inertia ixx="0" iyy="0" izz="0" ixy="0" ixz="0" iyz="0"/>
      <origin xyz="0.29 0 -0.17" rpy="0 0 0"/>
    </inertial>
  </link>
  <link name="Back_Left_Motor_Cap_1">
    <visual name="Back_Left_Motor_Cap_1_visual">
      <origin xyz="0 0 0" rpy="0 0 0"/>
      <geometry>
        <mesh filename="../custom_meshes/Back_Left_Motor_Cap_1.stl"/>
      </geometry>
      <material name="Back_Left_Motor_Cap_1_material">
        <color rgba="0 1 1 1"/>
      </material>
    </visual>
    <collision name="Back_Left_Motor_Cap_1_collision">
      <origin xyz="0 0 0" rpy="0 0 0"/>
      <geometry>
        <mesh filename="../custom_meshes/Back_Left_Motor_Cap_1.stl"/>
      </geometry>
    </collision>
    <inertial>
      <mass value="0"/>
      <inertia ixx="0" iyy="0" izz="0" ixy="0" ixz="0" iyz="0"/>
      <origin xyz="-0.29 0 0.17" rpy="0 0 0"/>
    </inertial>
  </link>
  <link name="Back_Right_Motor_Cap_1">
    <visual name="Back_Right_Motor_Cap_1_visual">
      <origin xyz="0 0 0" rpy="0 0 0"/>
      <geometry>
        <mesh filename="../custom_meshes/Back_Right_Motor_Cap_1.stl"/>
      </geometry>
      <material name="Back_Right_Motor_Cap_1_material">
        <color rgba="1 0 1 1"/>
      </material>
    </visual>
    <collision name="Back_Right_Motor_Cap_1_collision">
      <origin xyz="0 0 0" rpy="0 0 0"/>
      <geometry>
        <mesh filename="../custom_meshes/Back_Right_Motor_Cap_1.stl"/>
      </geometry>
    </collision>
    <inertial>
      <mass value="0"/>
      <inertia ixx="0" iyy="0" izz="0" ixy="0" ixz="0" iyz="0"/>
      <origin xyz="-0.29 0 -0.17" rpy="0 0 0"/>
    </inertial>
  </link>
  <link name="AK40_36_KV80_A_1">
    <visual name="AK40_36_KV80_A_1_visual">
      <origin xyz="0 0 0" rpy="0 0 0"/>
      <geometry>
        <mesh filename="../custom_meshes/AK40_36_KV80_A_1.stl"/>
      </geometry>
      <material name="AK40_36_KV80_A_1_material">
        <color rgba="1 1 0 1"/>
      </material>
    </visual>
    <collision name="AK40_36_KV80_A_1_collision">
      <origin xyz="0 0 0" rpy="0 0 0"/>
      <geometry>
        <mesh filename="../custom_meshes/AK40_36_KV80_A_1.stl"/>
      </geometry>
    </collision>
    <inertial>
      <mass value="1"/>
      <inertia ixx="1" iyy="1" izz="1" ixy="0" ixz="0" iyz="0"/>
      <origin xyz="0 0 0" rpy="0 0 0"/>
    </inertial>
  </link>
  <link name="AK40_36_KV80_A_2">
    <visual name="AK40_36_KV80_A_2_visual">
      <origin xyz="0 0 0" rpy="0 0 0"/>
      <geometry>
        <mesh filename="../custom_meshes/AK40_36_KV80_A_2.stl"/>
      </geometry>
      <material name="AK40_36_KV80_A_2_material">
        <color rgba="0 0 1 1"/>
      </material>
    </visual>
    <collision name="AK40_36_KV80_A_2_collision">
      <origin xyz="0 0 0" rpy="0 0 0"/>
      <geometry>
        <mesh filename="../custom_meshes/AK40_36_KV80_A_2.stl"/>
      </geometry>
    </collision>
    <inertial>
      <mass value="1"/>
      <inertia ixx="1" iyy="1" izz="1" ixy="0" ixz="0" iyz="0"/>
      <origin xyz="0 0 0" rpy="0 0 0"/>
    </inertial>
  </link>
  <link name="AK40_36_KV80_A_3">
    <visual name="AK40_36_KV80_A_3_visual">
      <origin xyz="0 0 0" rpy="0 0 0"/>
      <geometry>
        <mesh filename="../custom_meshes/AK40_36_KV80_A_3.stl"/>
      </geometry>
      <material name="AK40_36_KV80_A_3_material">
        <color rgba="0 0 0 1"/>
      </material>
    </visual>
    <collision name="AK40_36_KV80_A_3_collision">
      <origin xyz="0 0 0" rpy="0 0 0"/>
      <geometry>
        <mesh filename="../custom_meshes/AK40_36_KV80_A_3.stl"/>
      </geometry>
    </collision>
    <inertial>
      <mass value="1"/>
      <inertia ixx="1" iyy="1" izz="1" ixy="0" ixz="0" iyz="0"/>
      <origin xyz="0 0 0" rpy="0 0 0"/>
    </inertial>
  </link>
  <link name="AK40_36_KV80_A_4">
    <visual name="AK40_36_KV80_A_4_visual">
      <origin xyz="0 0 0" rpy="0 0 0"/>
      <geometry>
        <mesh filename="../custom_meshes/AK40_36_KV80_A_4.stl"/>
      </geometry>
      <material name="AK40_36_KV80_A_4_material">
        <color rgba="0 1 0 1"/>
      </material>
    </visual>
    <collision name="AK40_36_KV80_A_4_collision">
      <origin xyz="0 0 0" rpy="0 0 0"/>
      <geometry>
        <mesh filename="../custom_meshes/AK40_36_KV80_A_4.stl"/>
      </geometry>
    </collision>
    <inertial>
      <mass value="1"/>
      <inertia ixx="1" iyy="1" izz="1" ixy="0" ixz="0" iyz="0"/>
      <origin xyz="0 0 0" rpy="0 0 0"/>
    </inertial>
  </link>
  <link name="Right_Leg_Assembly_1_Outer_thigh_1">
    <visual name="Right_Leg_Assembly_1_Outer_thigh_1_visual">
      <origin xyz="0 0 0" rpy="0 0 0"/>
      <geometry>
        <mesh filename="../custom_meshes/Right_Leg_Assembly_1_Outer_thigh_1.stl"/>
      </geometry>
      <material name="Right_Leg_Assembly_1_Outer_thigh_1_material">
        <color rgba="1 1 0 1"/>
      </material>
    </visual>
    <collision name="Right_Leg_Assembly_1_Outer_thigh_1_collision">
      <origin xyz="0 0 0" rpy="0 0 0"/>
      <geometry>
        <mesh filename="../custom_meshes/Right_Leg_Assembly_1_Outer_thigh_1.stl"/>
      </geometry>
    </collision>
    <inertial>
      <mass value="0"/>
      <inertia ixx="0" iyy="0" izz="0" ixy="0" ixz="0" iyz="0"/>
      <origin xyz="0 0.130025 -0.07437531" rpy="0 0 0"/>
    </inertial>
  </link>
  <link name="Right_Leg_Assembly_4_Outer_thigh_1">
    <visual name="Right_Leg_Assembly_4_Outer_thigh_1_visual">
      <origin xyz="0 0 0" rpy="0 0 0"/>
      <geometry>
        <mesh filename="../custom_meshes/Right_Leg_Assembly_4_Outer_thigh_1.stl"/>
      </geometry>
      <material name="Right_Leg_Assembly_4_Outer_thigh_1_material">
        <color rgba="1 1 0 1"/>
      </material>
    </visual>
    <collision name="Right_Leg_Assembly_4_Outer_thigh_1_collision">
      <origin xyz="0 0 0" rpy="0 0 0"/>
      <geometry>
        <mesh filename="../custom_meshes/Right_Leg_Assembly_4_Outer_thigh_1.stl"/>
      </geometry>
    </collision>
    <inertial>
      <mass value="0"/>
      <inertia ixx="0" iyy="0" izz="0" ixy="0" ixz="0" iyz="0"/>
      <origin xyz="0 -0.130025 -0.07437531" rpy="0 0 0"/>
    </inertial>
  </link>
  <link name="Right_Leg_Assembly_3_Outer_thigh_1">
    <visual name="Right_Leg_Assembly_3_Outer_thigh_1_visual">
      <origin xyz="0 0 0" rpy="0 0 0"/>
      <geometry>
        <mesh filename="../custom_meshes/Right_Leg_Assembly_3_Outer_thigh_1.stl"/>
      </geometry>
      <material name="Right_Leg_Assembly_3_Outer_thigh_1_material">
        <color rgba="0 1 1 1"/>
      </material>
    </visual>
    <collision name="Right_Leg_Assembly_3_Outer_thigh_1_collision">
      <origin xyz="0 0 0" rpy="0 0 0"/>
      <geometry>
        <mesh filename="../custom_meshes/Right_Leg_Assembly_3_Outer_thigh_1.stl"/>
      </geometry>
    </collision>
    <inertial>
      <mass value="0"/>
      <inertia ixx="0" iyy="0" izz="0" ixy="0" ixz="0" iyz="0"/>
      <origin xyz="-0.130025 0 0.07437531" rpy="0 0 0"/>
    </inertial>
  </link>
  <link name="Right_Leg_Assembly_2_Outer_thigh_1">
    <visual name="Right_Leg_Assembly_2_Outer_thigh_1_visual">
      <origin xyz="0 0 0" rpy="0 0 0"/>
      <geometry>
        <mesh filename="../custom_meshes/Right_Leg_Assembly_2_Outer_thigh_1.stl"/>
      </geometry>
      <material name="Right_Leg_Assembly_2_Outer_thigh_1_material">
        <color rgba="1 0 1 1"/>
      </material>
    </visual>
    <collision name="Right_Leg_Assembly_2_Outer_thigh_1_collision">
      <origin xyz="0 0 0" rpy="0 0 0"/>
      <geometry>
        <mesh filename="../custom_meshes/Right_Leg_Assembly_2_Outer_thigh_1.stl"/>
      </geometry>
    </collision>
    <inertial>
      <mass value="0"/>
      <inertia ixx="0" iyy="0" izz="0" ixy="0" ixz="0" iyz="0"/>
      <origin xyz="-0.130025 0 0.07437531" rpy="0 0 0"/>
    </inertial>
  </link>
  <link name="Right_Leg_Assembly_1_Pivot_Pin_1">
    <visual name="Right_Leg_Assembly_1_Pivot_Pin_1_visual">
      <origin xyz="0 0 0" rpy="0 0 0"/>
      <geometry>
        <mesh filename="../custom_meshes/Right_Leg_Assembly_1_Pivot_Pin_1.stl"/>
      </geometry>
      <material name="Right_Leg_Assembly_1_Pivot_Pin_1_material">
        <color rgba="1 0 1 1"/>
      </material>
    </visual>
    <collision name="Right_Leg_Assembly_1_Pivot_Pin_1_collision">
      <origin xyz="0 0 0" rpy="0 0 0"/>
      <geometry>
        <mesh filename="../custom_meshes/Right_Leg_Assembly_1_Pivot_Pin_1.stl"/>
      </geometry>
    </collision>
    <inertial>
      <mass value="0"/>
      <inertia ixx="0" iyy="0" izz="0" ixy="0" ixz="0" iyz="0"/>
      <origin xyz="0.03164705 0.25747281 -0.04" rpy="0 0 0"/>
    </inertial>
  </link>
  <link name="Right_Leg_Assembly_1_Top_of_Leg_1">
    <visual name="Right_Leg_Assembly_1_Top_of_Leg_1_visual">
      <origin xyz="0 0 0" rpy="0 0 0"/>
      <geometry>
        <mesh filename="../custom_meshes/Right_Leg_Assembly_1_Top_of_Leg_1.stl"/>
      </geometry>
      <material name="Right_Leg_Assembly_1_Top_of_Leg_1_material">
        <color rgba="0 1 1 1"/>
      </material>
    </visual>
    <collision name="Right_Leg_Assembly_1_Top_of_Leg_1_collision">
      <origin xyz="0 0 0" rpy="0 0 0"/>
      <geometry>
        <mesh filename="../custom_meshes/Right_Leg_Assembly_1_Top_of_Leg_1.stl"/>
      </geometry>
    </collision>
    <inertial>
      <mass value="0.26008091"/>
      <inertia ixx="0.00042896442" iyy="0.00080627095" izz="0.00038594917" ixy="7.6753713e-09" ixz="-4.2678065e-08" iyz="2.0599334e-09"/>
      <origin xyz="4.5844305e-05 -0.0043562674 -0.074362696" rpy="0 0 0"/>
    </inertial>
  </link>
  <link name="Right_Leg_Assembly_4_Pivot_Pin_1">
    <visual name="Right_Leg_Assembly_4_Pivot_Pin_1_visual">
      <origin xyz="0 0 0" rpy="0 0 0"/>
      <geometry>
        <mesh filename="../custom_meshes/Right_Leg_Assembly_4_Pivot_Pin_1.stl"/>
      </geometry>
      <material name="Right_Leg_Assembly_4_Pivot_Pin_1_material">
        <color rgba="0 0 1 1"/>
      </material>
    </visual>
    <collision name="Right_Leg_Assembly_4_Pivot_Pin_1_collision">
      <origin xyz="0 0 0" rpy="0 0 0"/>
      <geometry>
        <mesh filename="../custom_meshes/Right_Leg_Assembly_4_Pivot_Pin_1.stl"/>
      </geometry>
    </collision>
    <inertial>
      <mass value="0"/>
      <inertia ixx="0" iyy="0" izz="0" ixy="0" ixz="0" iyz="0"/>
      <origin xyz="0.03164705 0.25747281 -0.04" rpy="0 0 0"/>
    </inertial>
  </link>
  <link name="Right_Leg_Assembly_4_Top_of_Leg_1">
    <visual name="Right_Leg_Assembly_4_Top_of_Leg_1_visual">
      <origin xyz="0 0 0" rpy="0 0 0"/>
      <geometry>
        <mesh filename="../custom_meshes/Right_Leg_Assembly_4_Top_of_Leg_1.stl"/>
      </geometry>
      <material name="Right_Leg_Assembly_4_Top_of_Leg_1_material">
        <color rgba="1 0.5 0 1"/>
      </material>
    </visual>
    <collision name="Right_Leg_Assembly_4_Top_of_Leg_1_collision">
      <origin xyz="0 0 0" rpy="0 0 0"/>
      <geometry>
        <mesh filename="../custom_meshes/Right_Leg_Assembly_4_Top_of_Leg_1.stl"/>
      </geometry>
    </collision>
    <inertial>
      <mass value="0.26008091"/>
      <inertia ixx="0.00042896442" iyy="0.00080627095" izz="0.00038594917" ixy="7.6753713e-09" ixz="-4.2678065e-08" iyz="2.0599334e-09"/>
      <origin xyz="4.5844305e-05 -0.0043562674 -0.074362696" rpy="0 0 0"/>
    </inertial>
  </link>
  <link name="Right_Leg_Assembly_3_Pivot_Pin_1">
    <visual name="Right_Leg_Assembly_3_Pivot_Pin_1_visual">
      <origin xyz="0 0 0" rpy="0 0 0"/>
      <geometry>
        <mesh filename="../custom_meshes/Right_Leg_Assembly_3_Pivot_Pin_1.stl"/>
      </geometry>
      <material name="Right_Leg_Assembly_3_Pivot_Pin_1_material">
        <color rgba="1 0 0.5 1"/>
      </material>
    </visual>
    <collision name="Right_Leg_Assembly_3_Pivot_Pin_1_collision">
      <origin xyz="0 0 0" rpy="0 0 0"/>
      <geometry>
        <mesh filename="../custom_meshes/Right_Leg_Assembly_3_Pivot_Pin_1.stl"/>
      </geometry>
    </collision>
    <inertial>
      <mass value="0"/>
      <inertia ixx="0" iyy="0" izz="0" ixy="0" ixz="0" iyz="0"/>
      <origin xyz="0.03164705 0.25747281 -0.04" rpy="0 0 0"/>
    </inertial>
  </link>
  <link name="Right_Leg_Assembly_3_Top_of_Leg_1">
    <visual name="Right_Leg_Assembly_3_Top_of_Leg_1_visual">
      <origin xyz="0 0 0" rpy="0 0 0"/>
      <geometry>
        <mesh filename="../custom_meshes/Right_Leg_Assembly_3_Top_of_Leg_1.stl"/>
      </geometry>
      <material name="Right_Leg_Assembly_3_Top_of_Leg_1_material">
        <color rgba="1 0 0 1"/>
      </material>
    </visual>
    <collision name="Right_Leg_Assembly_3_Top_of_Leg_1_collision">
      <origin xyz="0 0 0" rpy="0 0 0"/>
      <geometry>
        <mesh filename="../custom_meshes/Right_Leg_Assembly_3_Top_of_Leg_1.stl"/>
      </geometry>
    </collision>
    <inertial>
      <mass value="0.26008091"/>
      <inertia ixx="0.00042896442" iyy="0.00080627095" izz="0.00038594917" ixy="7.6753713e-09" ixz="-4.2678065e-08" iyz="2.0599334e-09"/>
      <origin xyz="4.5844305e-05 -0.0043562674 -0.074362696" rpy="0 0 0"/>
    </inertial>
  </link>
  <link name="Right_Leg_Assembly_2_Pivot_Pin_1">
    <visual name="Right_Leg_Assembly_2_Pivot_Pin_1_visual">
      <origin xyz="0 0 0" rpy="0 0 0"/>
      <geometry>
        <mesh filename="../custom_meshes/Right_Leg_Assembly_2_Pivot_Pin_1.stl"/>
      </geometry>
      <material name="Right_Leg_Assembly_2_Pivot_Pin_1_material">
        <color rgba="0 1 1 1"/>
      </material>
    </visual>
    <collision name="Right_Leg_Assembly_2_Pivot_Pin_1_collision">
      <origin xyz="0 0 0" rpy="0 0 0"/>
      <geometry>
        <mesh filename="../custom_meshes/Right_Leg_Assembly_2_Pivot_Pin_1.stl"/>
      </geometry>
    </collision>
    <inertial>
      <mass value="0"/>
      <inertia ixx="0" iyy="0" izz="0" ixy="0" ixz="0" iyz="0"/>
      <origin xyz="0.03164705 0.25747281 -0.04" rpy="0 0 0"/>
    </inertial>
  </link>
  <link name="Right_Leg_Assembly_2_Top_of_Leg_1">
    <visual name="Right_Leg_Assembly_2_Top_of_Leg_1_visual">
      <origin xyz="0 0 0" rpy="0 0 0"/>
      <geometry>
        <mesh filename="../custom_meshes/Right_Leg_Assembly_2_Top_of_Leg_1.stl"/>
      </geometry>
      <material name="Right_Leg_Assembly_2_Top_of_Leg_1_material">
        <color rgba="0 0 1 1"/>
      </material>
    </visual>
    <collision name="Right_Leg_Assembly_2_Top_of_Leg_1_collision">
      <origin xyz="0 0 0" rpy="0 0 0"/>
      <geometry>
        <mesh filename="../custom_meshes/Right_Leg_Assembly_2_Top_of_Leg_1.stl"/>
      </geometry>
    </collision>
    <inertial>
      <mass value="0.26008091"/>
      <inertia ixx="0.00042896442" iyy="0.00080627095" izz="0.00038594917" ixy="7.6753713e-09" ixz="-4.2678065e-08" iyz="2.0599334e-09"/>
      <origin xyz="4.5844305e-05 -0.0043562674 -0.074362696" rpy="0 0 0"/>
    </inertial>
  </link>
  <link name="Right_Leg_Assembly_1_Shin_1">
    <visual name="Right_Leg_Assembly_1_Shin_1_visual">
      <origin xyz="0 0 0" rpy="0 0 0"/>
      <geometry>
        <mesh filename="../custom_meshes/Right_Leg_Assembly_1_Shin_1.stl"/>
      </geometry>
      <material name="Right_Leg_Assembly_1_Shin_1_material">
        <color rgba="0 0 1 1"/>
      </material>
    </visual>
    <collision name="Right_Leg_Assembly_1_Shin_1_collision">
      <origin xyz="0 0 0" rpy="0 0 0"/>
      <geometry>
        <mesh filename="../custom_meshes/Right_Leg_Assembly_1_Shin_1.stl"/>
      </geometry>
    </collision>
    <inertial>
      <mass value="0.43019319"/>
      <inertia ixx="0.00016316235" iyy="0.0033347768" izz="0.0034692596" ixy="0.00015800528" ixz="0" iyz="0"/>
      <origin xyz="-0.03232495 0.00026305446 7.0346011e-19" rpy="0 0 0"/>
    </inertial>
  </link>
  <link name="Right_Leg_Assembly_1_Motor_Hinge_Pin_1">
    <visual name="Right_Leg_Assembly_1_Motor_Hinge_Pin_1_visual">
      <origin xyz="0 0 0" rpy="0 0 0"/>
      <geometry>
        <mesh filename="../custom_meshes/Right_Leg_Assembly_1_Motor_Hinge_Pin_1.stl"/>
      </geometry>
      <material name="Right_Leg_Assembly_1_Motor_Hinge_Pin_1_material">
        <color rgba="0 1 1 1"/>
      </material>
    </visual>
    <collision name="Right_Leg_Assembly_1_Motor_Hinge_Pin_1_collision">
      <origin xyz="0 0 0" rpy="0 0 0"/>
      <geometry>
        <mesh filename="../custom_meshes/Right_Leg_Assembly_1_Motor_Hinge_Pin_1.stl"/>
      </geometry>
    </collision>
    <inertial>
      <mass value="0"/>
      <inertia ixx="0" iyy="0" izz="0" ixy="0" ixz="0" iyz="0"/>
      <origin xyz="0 0.22 -0.032" rpy="0 0 0"/>
    </inertial>
  </link>
  <link name="Right_Leg_Assembly_4_Shin_1">
    <visual name="Right_Leg_Assembly_4_Shin_1_visual">
      <origin xyz="0 0 0" rpy="0 0 0"/>
      <geometry>
        <mesh filename="../custom_meshes/Right_Leg_Assembly_4_Shin_1.stl"/>
      </geometry>
      <material name="Right_Leg_Assembly_4_Shin_1_material">
        <color rgba="0 1 0 1"/>
      </material>
    </visual>
    <collision name="Right_Leg_Assembly_4_Shin_1_collision">
      <origin xyz="0 0 0" rpy="0 0 0"/>
      <geometry>
        <mesh filename="../custom_meshes/Right_Leg_Assembly_4_Shin_1.stl"/>
      </geometry>
    </collision>
    <inertial>
      <mass value="0.43019319"/>
      <inertia ixx="0.00016316235" iyy="0.0033347768" izz="0.0034692596" ixy="0.00015800528" ixz="0" iyz="0"/>
      <origin xyz="-0.03232495 0.00026305446 6.2654763e-19" rpy="0 0 0"/>
    </inertial>
  </link>
  <link name="Right_Leg_Assembly_4_Motor_Hinge_Pin_1">
    <visual name="Right_Leg_Assembly_4_Motor_Hinge_Pin_1_visual">
      <origin xyz="0 0 0" rpy="0 0 0"/>
      <geometry>
        <mesh filename="../custom_meshes/Right_Leg_Assembly_4_Motor_Hinge_Pin_1.stl"/>
      </geometry>
      <material name="Right_Leg_Assembly_4_Motor_Hinge_Pin_1_material">
        <color rgba="0 0 1 1"/>
      </material>
    </visual>
    <collision name="Right_Leg_Assembly_4_Motor_Hinge_Pin_1_collision">
      <origin xyz="0 0 0" rpy="0 0 0"/>
      <geometry>
        <mesh filename="../custom_meshes/Right_Leg_Assembly_4_Motor_Hinge_Pin_1.stl"/>
      </geometry>
    </collision>
    <inertial>
      <mass value="0"/>
      <inertia ixx="0" iyy="0" izz="0" ixy="0" ixz="0" iyz="0"/>
      <origin xyz="0 0.22 -0.032" rpy="0 0 0"/>
    </inertial>
  </link>
  <link name="Right_Leg_Assembly_3_Shin_1">
    <visual name="Right_Leg_Assembly_3_Shin_1_visual">
      <origin xyz="0 0 0" rpy="0 0 0"/>
      <geometry>
        <mesh filename="../custom_meshes/Right_Leg_Assembly_3_Shin_1.stl"/>
      </geometry>
      <material name="Right_Leg_Assembly_3_Shin_1_material">
        <color rgba="1 0 0 1"/>
      </material>
    </visual>
    <collision name="Right_Leg_Assembly_3_Shin_1_collision">
      <origin xyz="0 0 0" rpy="0 0 0"/>
      <geometry>
        <mesh filename="../custom_meshes/Right_Leg_Assembly_3_Shin_1.stl"/>
      </geometry>
    </collision>
    <inertial>
      <mass value="0.43019319"/>
      <inertia ixx="0.00016316235" iyy="0.0033347768" izz="0.0034692596" ixy="0.00015800528" ixz="0" iyz="0"/>
      <origin xyz="-0.03232495 0.00026305446 5.363043e-19" rpy="0 0 0"/>
    </inertial>
  </link>
  <link name="Right_Leg_Assembly_3_Motor_Hinge_Pin_1">
    <visual name="Right_Leg_Assembly_3_Motor_Hinge_Pin_1_visual">
      <origin xyz="0 0 0" rpy="0 0 0"/>
      <geometry>
        <mesh filename="../custom_meshes/Right_Leg_Assembly_3_Motor_Hinge_Pin_1.stl"/>
      </geometry>
      <material name="Right_Leg_Assembly_3_Motor_Hinge_Pin_1_material">
        <color rgba="0 1 0 1"/>
      </material>
    </visual>
    <collision name="Right_Leg_Assembly_3_Motor_Hinge_Pin_1_collision">
      <origin xyz="0 0 0" rpy="0 0 0"/>
      <geometry>
        <mesh filename="../custom_meshes/Right_Leg_Assembly_3_Motor_Hinge_Pin_1.stl"/>
      </geometry>
    </collision>
    <inertial>
      <mass value="0"/>
      <inertia ixx="0" iyy="0" izz="0" ixy="0" ixz="0" iyz="0"/>
      <origin xyz="0 0.22 -0.032" rpy="0 0 0"/>
    </inertial>
  </link>
  <link name="Right_Leg_Assembly_2_Shin_1">
    <visual name="Right_Leg_Assembly_2_Shin_1_visual">
      <origin xyz="0 0 0" rpy="0 0 0"/>
      <geometry>
        <mesh filename="../custom_meshes/Right_Leg_Assembly_2_Shin_1.stl"/>
      </geometry>
      <material name="Right_Leg_Assembly_2_Shin_1_material">
        <color rgba="1 1 0 1"/>
      </material>
    </visual>
    <collision name="Right_Leg_Assembly_2_Shin_1_collision">
      <origin xyz="0 0 0" rpy="0 0 0"/>
      <geometry>
        <mesh filename="../custom_meshes/Right_Leg_Assembly_2_Shin_1.stl"/>
      </geometry>
    </collision>
    <inertial>
      <mass value="0.43019319"/>
      <inertia ixx="0.00016316235" iyy="0.0033347768" izz="0.0034692596" ixy="0.00015800528" ixz="0" iyz="0"/>
      <origin xyz="-0.03232495 0.00026305446 7.0059769e-19" rpy="0 0 0"/>
    </inertial>
  </link>
  <link name="Right_Leg_Assembly_2_Motor_Hinge_Pin_1">
    <visual name="Right_Leg_Assembly_2_Motor_Hinge_Pin_1_visual">
      <origin xyz="0 0 0" rpy="0 0 0"/>
      <geometry>
        <mesh filename="../custom_meshes/Right_Leg_Assembly_2_Motor_Hinge_Pin_1.stl"/>
      </geometry>
      <material name="Right_Leg_Assembly_2_Motor_Hinge_Pin_1_material">
        <color rgba="1 0 0.5 1"/>
      </material>
    </visual>
    <collision name="Right_Leg_Assembly_2_Motor_Hinge_Pin_1_collision">
      <origin xyz="0 0 0" rpy="0 0 0"/>
      <geometry>
        <mesh filename="../custom_meshes/Right_Leg_Assembly_2_Motor_Hinge_Pin_1.stl"/>
      </geometry>
    </collision>
    <inertial>
      <mass value="0"/>
      <inertia ixx="0" iyy="0" izz="0" ixy="0" ixz="0" iyz="0"/>
      <origin xyz="0 0.22 -0.032" rpy="0 0 0"/>
    </inertial>
  </link>
  <link name="Right_Leg_Assembly_1_Non_Pivot_Pin_1">
    <visual name="Right_Leg_Assembly_1_Non_Pivot_Pin_1_visual">
      <origin xyz="0 0 0" rpy="0 0 0"/>
      <geometry>
        <mesh filename="../custom_meshes/Right_Leg_Assembly_1_Non_Pivot_Pin_1.stl"/>
      </geometry>
      <material name="Right_Leg_Assembly_1_Non_Pivot_Pin_1_material">
        <color rgba="1 0 0.5 1"/>
      </material>
    </visual>
    <collision name="Right_Leg_Assembly_1_Non_Pivot_Pin_1_collision">
      <origin xyz="0 0 0" rpy="0 0 0"/>
      <geometry>
        <mesh filename="../custom_meshes/Right_Leg_Assembly_1_Non_Pivot_Pin_1.stl"/>
      </geometry>
    </collision>
    <inertial>
      <mass value="0"/>
      <inertia ixx="0" iyy="0" izz="0" ixy="0" ixz="0" iyz="0"/>
      <origin xyz="0 0.25420522 0.00045" rpy="0 0 0"/>
    </inertial>
  </link>
  <link name="Right_Leg_Assembly_1_Feet_1">
    <visual name="Right_Leg_Assembly_1_Feet_1_visual">
      <origin xyz="0 0 0" rpy="0 0 0"/>
      <geometry>
        <mesh filename="../custom_meshes/Right_Leg_Assembly_1_Feet_1.stl"/>
      </geometry>
      <material name="Right_Leg_Assembly_1_Feet_1_material">
        <color rgba="1 1 1 1"/>
      </material>
    </visual>
    <collision name="Right_Leg_Assembly_1_Feet_1_collision">
      <origin xyz="0 0 0" rpy="0 0 0"/>
      <geometry>
        <mesh filename="../custom_meshes/Right_Leg_Assembly_1_Feet_1.stl"/>
      </geometry>
    </collision>
    <inertial>
      <mass value="0"/>
      <inertia ixx="0" iyy="0" izz="0" ixy="0" ixz="0" iyz="0"/>
      <origin xyz="0 -0.2538071 0.2145931" rpy="0 0 0"/>
    </inertial>
  </link>
  <link name="Right_Leg_Assembly_1_Motor_Hinge_1">
    <visual name="Right_Leg_Assembly_1_Motor_Hinge_1_visual">
      <origin xyz="0 0 0" rpy="0 0 0"/>
      <geometry>
        <mesh filename="../custom_meshes/Right_Leg_Assembly_1_Motor_Hinge_1.stl"/>
      </geometry>
      <material name="Right_Leg_Assembly_1_Motor_Hinge_1_material">
        <color rgba="0 1 1 1"/>
      </material>
    </visual>
    <collision name="Right_Leg_Assembly_1_Motor_Hinge_1_collision">
      <origin xyz="0 0 0" rpy="0 0 0"/>
      <geometry>
        <mesh filename="../custom_meshes/Right_Leg_Assembly_1_Motor_Hinge_1.stl"/>
      </geometry>
    </collision>
    <inertial>
      <mass value="0"/>
      <inertia ixx="0" iyy="0" izz="0" ixy="0" ixz="0" iyz="0"/>
      <origin xyz="0 0.22 0" rpy="0 0 0"/>
    </inertial>
  </link>
  <link name="Right_Leg_Assembly_4_Non_Pivot_Pin_1">
    <visual name="Right_Leg_Assembly_4_Non_Pivot_Pin_1_visual">
      <origin xyz="0 0 0" rpy="0 0 0"/>
      <geometry>
        <mesh filename="../custom_meshes/Right_Leg_Assembly_4_Non_Pivot_Pin_1.stl"/>
      </geometry>
      <material name="Right_Leg_Assembly_4_Non_Pivot_Pin_1_material">
        <color rgba="1 1 0 1"/>
      </material>
    </visual>
    <collision name="Right_Leg_Assembly_4_Non_Pivot_Pin_1_collision">
      <origin xyz="0 0 0" rpy="0 0 0"/>
      <geometry>
        <mesh filename="../custom_meshes/Right_Leg_Assembly_4_Non_Pivot_Pin_1.stl"/>
      </geometry>
    </collision>
    <inertial>
      <mass value="0"/>
      <inertia ixx="0" iyy="0" izz="0" ixy="0" ixz="0" iyz="0"/>
      <origin xyz="0 0.25420522 0.00045" rpy="0 0 0"/>
    </inertial>
  </link>
  <link name="Right_Leg_Assembly_4_Feet_1">
    <visual name="Right_Leg_Assembly_4_Feet_1_visual">
      <origin xyz="0 0 0" rpy="0 0 0"/>
      <geometry>
        <mesh filename="../custom_meshes/Right_Leg_Assembly_4_Feet_1.stl"/>
      </geometry>
      <material name="Right_Leg_Assembly_4_Feet_1_material">
        <color rgba="1 0.5 0 1"/>
      </material>
    </visual>
    <collision name="Right_Leg_Assembly_4_Feet_1_collision">
      <origin xyz="0 0 0" rpy="0 0 0"/>
      <geometry>
        <mesh filename="../custom_meshes/Right_Leg_Assembly_4_Feet_1.stl"/>
      </geometry>
    </collision>
    <inertial>
      <mass value="0"/>
      <inertia ixx="0" iyy="0" izz="0" ixy="0" ixz="0" iyz="0"/>
      <origin xyz="0 -0.2538071 0.2145931" rpy="0 0 0"/>
    </inertial>
  </link>
  <link name="Right_Leg_Assembly_4_Motor_Hinge_1">
    <visual name="Right_Leg_Assembly_4_Motor_Hinge_1_visual">
      <origin xyz="0 0 0" rpy="0 0 0"/>
      <geometry>
        <mesh filename="../custom_meshes/Right_Leg_Assembly_4_Motor_Hinge_1.stl"/>
      </geometry>
      <material name="Right_Leg_Assembly_4_Motor_Hinge_1_material">
        <color rgba="1 0 1 1"/>
      </material>
    </visual>
    <collision name="Right_Leg_Assembly_4_Motor_Hinge_1_collision">
      <origin xyz="0 0 0" rpy="0 0 0"/>
      <geometry>
        <mesh filename="../custom_meshes/Right_Leg_Assembly_4_Motor_Hinge_1.stl"/>
      </geometry>
    </collision>
    <inertial>
      <mass value="0"/>
      <inertia ixx="0" iyy="0" izz="0" ixy="0" ixz="0" iyz="0"/>
      <origin xyz="0 0.22 0" rpy="0 0 0"/>
    </inertial>
  </link>
  <link name="Right_Leg_Assembly_3_Non_Pivot_Pin_1">
    <visual name="Right_Leg_Assembly_3_Non_Pivot_Pin_1_visual">
      <origin xyz="0 0 0" rpy="0 0 0"/>
      <geometry>
        <mesh filename="../custom_meshes/Right_Leg_Assembly_3_Non_Pivot_Pin_1.stl"/>
      </geometry>
      <material name="Right_Leg_Assembly_3_Non_Pivot_Pin_1_material">
        <color rgba="0 1 0 1"/>
      </material>
    </visual>
    <collision name="Right_Leg_Assembly_3_Non_Pivot_Pin_1_collision">
      <origin xyz="0 0 0" rpy="0 0 0"/>
      <geometry>
        <mesh filename="../custom_meshes/Right_Leg_Assembly_3_Non_Pivot_Pin_1.stl"/>
      </geometry>
    </collision>
    <inertial>
      <mass value="0"/>
      <inertia ixx="0" iyy="0" izz="0" ixy="0" ixz="0" iyz="0"/>
      <origin xyz="0 0.25420522 0.00045" rpy="0 0 0"/>
    </inertial>
  </link>
  <link name="Right_Leg_Assembly_3_Feet_1">
    <visual name="Right_Leg_Assembly_3_Feet_1_visual">
      <origin xyz="0 0 0" rpy="0 0 0"/>
      <geometry>
        <mesh filename="../custom_meshes/Right_Leg_Assembly_3_Feet_1.stl"/>
      </geometry>
      <material name="Right_Leg_Assembly_3_Feet_1_material">
        <color rgba="1 0 0 1"/>
      </material>
    </visual>
    <collision name="Right_Leg_Assembly_3_Feet_1_collision">
      <origin xyz="0 0 0" rpy="0 0 0"/>
      <geometry>
        <mesh filename="../custom_meshes/Right_Leg_Assembly_3_Feet_1.stl"/>
      </geometry>
    </collision>
    <inertial>
      <mass value="0"/>
      <inertia ixx="0" iyy="0" izz="0" ixy="0" ixz="0" iyz="0"/>
      <origin xyz="0 -0.2538071 0.2145931" rpy="0 0 0"/>
    </inertial>
  </link>
  <link name="Right_Leg_Assembly_3_Motor_Hinge_1">
    <visual name="Right_Leg_Assembly_3_Motor_Hinge_1_visual">
      <origin xyz="0 0 0" rpy="0 0 0"/>
      <geometry>
        <mesh filename="../custom_meshes/Right_Leg_Assembly_3_Motor_Hinge_1.stl"/>
      </geometry>
      <material name="Right_Leg_Assembly_3_Motor_Hinge_1_material">
        <color rgba="1 0.5 0 1"/>
      </material>
    </visual>
    <collision name="Right_Leg_Assembly_3_Motor_Hinge_1_collision">
      <origin xyz="0 0 0" rpy="0 0 0"/>
      <geometry>
        <mesh filename="../custom_meshes/Right_Leg_Assembly_3_Motor_Hinge_1.stl"/>
      </geometry>
    </collision>
    <inertial>
      <mass value="0"/>
      <inertia ixx="0" iyy="0" izz="0" ixy="0" ixz="0" iyz="0"/>
      <origin xyz="0 0.22 0" rpy="0 0 0"/>
    </inertial>
  </link>
  <link name="Right_Leg_Assembly_2_Non_Pivot_Pin_1">
    <visual name="Right_Leg_Assembly_2_Non_Pivot_Pin_1_visual">
      <origin xyz="0 0 0" rpy="0 0 0"/>
      <geometry>
        <mesh filename="../custom_meshes/Right_Leg_Assembly_2_Non_Pivot_Pin_1.stl"/>
      </geometry>
      <material name="Right_Leg_Assembly_2_Non_Pivot_Pin_1_material">
        <color rgba="1 1 1 1"/>
      </material>
    </visual>
    <collision name="Right_Leg_Assembly_2_Non_Pivot_Pin_1_collision">
      <origin xyz="0 0 0" rpy="0 0 0"/>
      <geometry>
        <mesh filename="../custom_meshes/Right_Leg_Assembly_2_Non_Pivot_Pin_1.stl"/>
      </geometry>
    </collision>
    <inertial>
      <mass value="0"/>
      <inertia ixx="0" iyy="0" izz="0" ixy="0" ixz="0" iyz="0"/>
      <origin xyz="0 0.25420522 0.00045" rpy="0 0 0"/>
    </inertial>
  </link>
  <link name="Right_Leg_Assembly_2_Feet_1">
    <visual name="Right_Leg_Assembly_2_Feet_1_visual">
      <origin xyz="0 0 0" rpy="0 0 0"/>
      <geometry>
        <mesh filename="../custom_meshes/Right_Leg_Assembly_2_Feet_1.stl"/>
      </geometry>
      <material name="Right_Leg_Assembly_2_Feet_1_material">
        <color rgba="1 1 0 1"/>
      </material>
    </visual>
    <collision name="Right_Leg_Assembly_2_Feet_1_collision">
      <origin xyz="0 0 0" rpy="0 0 0"/>
      <geometry>
        <mesh filename="../custom_meshes/Right_Leg_Assembly_2_Feet_1.stl"/>
      </geometry>
    </collision>
    <inertial>
      <mass value="0"/>
      <inertia ixx="0" iyy="0" izz="0" ixy="0" ixz="0" iyz="0"/>
      <origin xyz="0 -0.2538071 0.2145931" rpy="0 0 0"/>
    </inertial>
  </link>
  <link name="Right_Leg_Assembly_2_Motor_Hinge_1">
    <visual name="Right_Leg_Assembly_2_Motor_Hinge_1_visual">
      <origin xyz="0 0 0" rpy="0 0 0"/>
      <geometry>
        <mesh filename="../custom_meshes/Right_Leg_Assembly_2_Motor_Hinge_1.stl"/>
      </geometry>
      <material name="Right_Leg_Assembly_2_Motor_Hinge_1_material">
        <color rgba="1 1 1 1"/>
      </material>
    </visual>
    <collision name="Right_Leg_Assembly_2_Motor_Hinge_1_collision">
      <origin xyz="0 0 0" rpy="0 0 0"/>
      <geometry>
        <mesh filename="../custom_meshes/Right_Leg_Assembly_2_Motor_Hinge_1.stl"/>
      </geometry>
    </collision>
    <inertial>
      <mass value="0"/>
      <inertia ixx="0" iyy="0" izz="0" ixy="0" ixz="0" iyz="0"/>
      <origin xyz="0 0.22 0" rpy="0 0 0"/>
    </inertial>
  </link>
  <link name="Right_Leg_Assembly_1_Connector_Screw_to_Shin_1">
    <visual name="Right_Leg_Assembly_1_Connector_Screw_to_Shin_1_visual">
      <origin xyz="0 0 0" rpy="0 0 0"/>
      <geometry>
        <mesh filename="../custom_meshes/Right_Leg_Assembly_1_Connector_Screw_to_Shin_1.stl"/>
      </geometry>
      <material name="Right_Leg_Assembly_1_Connector_Screw_to_Shin_1_material">
        <color rgba="1 0 0 1"/>
      </material>
    </visual>
    <collision name="Right_Leg_Assembly_1_Connector_Screw_to_Shin_1_collision">
      <origin xyz="0 0 0" rpy="0 0 0"/>
      <geometry>
        <mesh filename="../custom_meshes/Right_Leg_Assembly_1_Connector_Screw_to_Shin_1.stl"/>
      </geometry>
    </collision>
    <inertial>
      <mass value="0"/>
      <inertia ixx="0" iyy="0" izz="0" ixy="0" ixz="0" iyz="0"/>
      <origin xyz="0 0.25420522 -0.0215" rpy="0 0 0"/>
    </inertial>
  </link>
  <link name="Right_Leg_Assembly_1_AK40_36_KV80_A_1">
    <visual name="Right_Leg_Assembly_1_AK40_36_KV80_A_1_visual">
      <origin xyz="0 0 0" rpy="0 0 0"/>
      <geometry>
        <mesh filename="../custom_meshes/Right_Leg_Assembly_1_AK40_36_KV80_A_1.stl"/>
      </geometry>
      <material name="Right_Leg_Assembly_1_AK40_36_KV80_A_1_material">
        <color rgba="1 0 0.5 1"/>
      </material>
    </visual>
    <collision name="Right_Leg_Assembly_1_AK40_36_KV80_A_1_collision">
      <origin xyz="0 0 0" rpy="0 0 0"/>
      <geometry>
        <mesh filename="../custom_meshes/Right_Leg_Assembly_1_AK40_36_KV80_A_1.stl"/>
      </geometry>
    </collision>
    <inertial>
      <mass value="1"/>
      <inertia ixx="1" iyy="1" izz="1" ixy="0" ixz="0" iyz="0"/>
      <origin xyz="0 0 0" rpy="0 0 0"/>
    </inertial>
  </link>
  <link name="Right_Leg_Assembly_4_Connector_Screw_to_Shin_1">
    <visual name="Right_Leg_Assembly_4_Connector_Screw_to_Shin_1_visual">
      <origin xyz="0 0 0" rpy="0 0 0"/>
      <geometry>
        <mesh filename="../custom_meshes/Right_Leg_Assembly_4_Connector_Screw_to_Shin_1.stl"/>
      </geometry>
      <material name="Right_Leg_Assembly_4_Connector_Screw_to_Shin_1_material">
        <color rgba="1 0 1 1"/>
      </material>
    </visual>
    <collision name="Right_Leg_Assembly_4_Connector_Screw_to_Shin_1_collision">
      <origin xyz="0 0 0" rpy="0 0 0"/>
      <geometry>
        <mesh filename="../custom_meshes/Right_Leg_Assembly_4_Connector_Screw_to_Shin_1.stl"/>
      </geometry>
    </collision>
    <inertial>
      <mass value="0"/>
      <inertia ixx="0" iyy="0" izz="0" ixy="0" ixz="0" iyz="0"/>
      <origin xyz="0 0.25420522 -0.0215" rpy="0 0 0"/>
    </inertial>
  </link>
  <link name="Right_Leg_Assembly_4_AK40_36_KV80_A_1">
    <visual name="Right_Leg_Assembly_4_AK40_36_KV80_A_1_visual">
      <origin xyz="0 0 0" rpy="0 0 0"/>
      <geometry>
        <mesh filename="../custom_meshes/Right_Leg_Assembly_4_AK40_36_KV80_A_1.stl"/>
      </geometry>
      <material name="Right_Leg_Assembly_4_AK40_36_KV80_A_1_material">
        <color rgba="0 1 0 1"/>
      </material>
    </visual>
    <collision name="Right_Leg_Assembly_4_AK40_36_KV80_A_1_collision">
      <origin xyz="0 0 0" rpy="0 0 0"/>
      <geometry>
        <mesh filename="../custom_meshes/Right_Leg_Assembly_4_AK40_36_KV80_A_1.stl"/>
      </geometry>
    </collision>
    <inertial>
      <mass value="1"/>
      <inertia ixx="1" iyy="1" izz="1" ixy="0" ixz="0" iyz="0"/>
      <origin xyz="0 0 0" rpy="0 0 0"/>
    </inertial>
  </link>
  <link name="Right_Leg_Assembly_3_Connector_Screw_to_Shin_1">
    <visual name="Right_Leg_Assembly_3_Connector_Screw_to_Shin_1_visual">
      <origin xyz="0 0 0" rpy="0 0 0"/>
      <geometry>
        <mesh filename="../custom_meshes/Right_Leg_Assembly_3_Connector_Screw_to_Shin_1.stl"/>
      </geometry>
      <material name="Right_Leg_Assembly_3_Connector_Screw_to_Shin_1_material">
        <color rgba="0 0 1 1"/>
      </material>
    </visual>
    <collision name="Right_Leg_Assembly_3_Connector_Screw_to_Shin_1_collision">
      <origin xyz="0 0 0" rpy="0 0 0"/>
      <geometry>
        <mesh filename="../custom_meshes/Right_Leg_Assembly_3_Connector_Screw_to_Shin_1.stl"/>
      </geometry>
    </collision>
    <inertial>
      <mass value="0"/>
      <inertia ixx="0" iyy="0" izz="0" ixy="0" ixz="0" iyz="0"/>
      <origin xyz="0 0.25420522 -0.0215" rpy="0 0 0"/>
    </inertial>
  </link>
  <link name="Right_Leg_Assembly_3_AK40_36_KV80_A_1">
    <visual name="Right_Leg_Assembly_3_AK40_36_KV80_A_1_visual">
      <origin xyz="0 0 0" rpy="0 0 0"/>
      <geometry>
        <mesh filename="../custom_meshes/Right_Leg_Assembly_3_AK40_36_KV80_A_1.stl"/>
      </geometry>
      <material name="Right_Leg_Assembly_3_AK40_36_KV80_A_1_material">
        <color rgba="0 1 0 1"/>
      </material>
    </visual>
    <collision name="Right_Leg_Assembly_3_AK40_36_KV80_A_1_collision">
      <origin xyz="0 0 0" rpy="0 0 0"/>
      <geometry>
        <mesh filename="../custom_meshes/Right_Leg_Assembly_3_AK40_36_KV80_A_1.stl"/>
      </geometry>
    </collision>
    <inertial>
      <mass value="1"/>
      <inertia ixx="1" iyy="1" izz="1" ixy="0" ixz="0" iyz="0"/>
      <origin xyz="0 0 0" rpy="0 0 0"/>
    </inertial>
  </link>
  <link name="Right_Leg_Assembly_2_Connector_Screw_to_Shin_1">
    <visual name="Right_Leg_Assembly_2_Connector_Screw_to_Shin_1_visual">
      <origin xyz="0 0 0" rpy="0 0 0"/>
      <geometry>
        <mesh filename="../custom_meshes/Right_Leg_Assembly_2_Connector_Screw_to_Shin_1.stl"/>
      </geometry>
      <material name="Right_Leg_Assembly_2_Connector_Screw_to_Shin_1_material">
        <color rgba="1 1 1 1"/>
      </material>
    </visual>
    <collision name="Right_Leg_Assembly_2_Connector_Screw_to_Shin_1_collision">
      <origin xyz="0 0 0" rpy="0 0 0"/>
      <geometry>
        <mesh filename="../custom_meshes/Right_Leg_Assembly_2_Connector_Screw_to_Shin_1.stl"/>
      </geometry>
    </collision>
    <inertial>
      <mass value="0"/>
      <inertia ixx="0" iyy="0" izz="0" ixy="0" ixz="0" iyz="0"/>
      <origin xyz="0 0.25420522 -0.0215" rpy="0 0 0"/>
    </inertial>
  </link>
  <link name="Right_Leg_Assembly_2_AK40_36_KV80_A_1">
    <visual name="Right_Leg_Assembly_2_AK40_36_KV80_A_1_visual">
      <origin xyz="0 0 0" rpy="0 0 0"/>
      <geometry>
        <mesh filename="../custom_meshes/Right_Leg_Assembly_2_AK40_36_KV80_A_1.stl"/>
      </geometry>
      <material name="Right_Leg_Assembly_2_AK40_36_KV80_A_1_material">
        <color rgba="1 1 0 1"/>
      </material>
    </visual>
    <collision name="Right_Leg_Assembly_2_AK40_36_KV80_A_1_collision">
      <origin xyz="0 0 0" rpy="0 0 0"/>
      <geometry>
        <mesh filename="../custom_meshes/Right_Leg_Assembly_2_AK40_36_KV80_A_1.stl"/>
      </geometry>
    </collision>
    <inertial>
      <mass value="1"/>
      <inertia ixx="1" iyy="1" izz="1" ixy="0" ixz="0" iyz="0"/>
      <origin xyz="0 0 0" rpy="0 0 0"/>
    </inertial>
  </link>
  <link name="Right_Leg_Assembly_1_Nut_for_Screw_1">
    <visual name="Right_Leg_Assembly_1_Nut_for_Screw_1_visual">
      <origin xyz="0 0 0" rpy="0 0 0"/>
      <geometry>
        <mesh filename="../custom_meshes/Right_Leg_Assembly_1_Nut_for_Screw_1.stl"/>
      </geometry>
      <material name="Right_Leg_Assembly_1_Nut_for_Screw_1_material">
        <color rgba="0 1 0 1"/>
      </material>
    </visual>
    <collision name="Right_Leg_Assembly_1_Nut_for_Screw_1_collision">
      <origin xyz="0 0 0" rpy="0 0 0"/>
      <geometry>
        <mesh filename="../custom_meshes/Right_Leg_Assembly_1_Nut_for_Screw_1.stl"/>
      </geometry>
    </collision>
    <inertial>
      <mass value="0"/>
      <inertia ixx="0" iyy="0" izz="0" ixy="0" ixz="0" iyz="0"/>
      <origin xyz="0 0 0.02876606" rpy="0 0 0"/>
    </inertial>
  </link>
  <link name="Right_Leg_Assembly_1_Screw_for_Nut_1">
    <visual name="Right_Leg_Assembly_1_Screw_for_Nut_1_visual">
      <origin xyz="0 0 0" rpy="0 0 0"/>
      <geometry>
        <mesh filename="../custom_meshes/Right_Leg_Assembly_1_Screw_for_Nut_1.stl"/>
      </geometry>
      <material name="Right_Leg_Assembly_1_Screw_for_Nut_1_material">
        <color rgba="1 1 1 1"/>
      </material>
    </visual>
    <collision name="Right_Leg_Assembly_1_Screw_for_Nut_1_collision">
      <origin xyz="0 0 0" rpy="0 0 0"/>
      <geometry>
        <mesh filename="../custom_meshes/Right_Leg_Assembly_1_Screw_for_Nut_1.stl"/>
      </geometry>
    </collision>
    <inertial>
      <mass value="0.05488579"/>
      <inertia ixx="0.00018843062" iyy="0.00018842875" izz="2.8454558e-06" ixy="-2.9131939e-09" ixz="4.291466e-08" iyz="1.2768433e-07"/>
      <origin xyz="1.0934975e-05 -2.6279199e-05 0.086328998" rpy="0 0 0"/>
    </inertial>
  </link>
  <link name="Right_Leg_Assembly_4_Nut_for_Screw_1">
    <visual name="Right_Leg_Assembly_4_Nut_for_Screw_1_visual">
      <origin xyz="0 0 0" rpy="0 0 0"/>
      <geometry>
        <mesh filename="../custom_meshes/Right_Leg_Assembly_4_Nut_for_Screw_1.stl"/>
      </geometry>
      <material name="Right_Leg_Assembly_4_Nut_for_Screw_1_material">
        <color rgba="0 1 1 1"/>
      </material>
    </visual>
    <collision name="Right_Leg_Assembly_4_Nut_for_Screw_1_collision">
      <origin xyz="0 0 0" rpy="0 0 0"/>
      <geometry>
        <mesh filename="../custom_meshes/Right_Leg_Assembly_4_Nut_for_Screw_1.stl"/>
      </geometry>
    </collision>
    <inertial>
      <mass value="0"/>
      <inertia ixx="0" iyy="0" izz="0" ixy="0" ixz="0" iyz="0"/>
      <origin xyz="0 0 0.02876606" rpy="0 0 0"/>
    </inertial>
  </link>
  <link name="Right_Leg_Assembly_4_Screw_for_Nut_1">
    <visual name="Right_Leg_Assembly_4_Screw_for_Nut_1_visual">
      <origin xyz="0 0 0" rpy="0 0 0"/>
      <geometry>
        <mesh filename="../custom_meshes/Right_Leg_Assembly_4_Screw_for_Nut_1.stl"/>
      </geometry>
      <material name="Right_Leg_Assembly_4_Screw_for_Nut_1_material">
        <color rgba="0 1 1 1"/>
      </material>
    </visual>
    <collision name="Right_Leg_Assembly_4_Screw_for_Nut_1_collision">
      <origin xyz="0 0 0" rpy="0 0 0"/>
      <geometry>
        <mesh filename="../custom_meshes/Right_Leg_Assembly_4_Screw_for_Nut_1.stl"/>
      </geometry>
    </collision>
    <inertial>
      <mass value="0.05488579"/>
      <inertia ixx="0.00018843062" iyy="0.00018842875" izz="2.8454558e-06" ixy="-2.9131939e-09" ixz="4.291466e-08" iyz="1.2768433e-07"/>
      <origin xyz="1.0934975e-05 -2.6279199e-05 0.086328998" rpy="0 0 0"/>
    </inertial>
  </link>
  <link name="Right_Leg_Assembly_3_Nut_for_Screw_1">
    <visual name="Right_Leg_Assembly_3_Nut_for_Screw_1_visual">
      <origin xyz="0 0 0" rpy="0 0 0"/>
      <geometry>
        <mesh filename="../custom_meshes/Right_Leg_Assembly_3_Nut_for_Screw_1.stl"/>
      </geometry>
      <material name="Right_Leg_Assembly_3_Nut_for_Screw_1_material">
        <color rgba="0 0 0 1"/>
      </material>
    </visual>
    <collision name="Right_Leg_Assembly_3_Nut_for_Screw_1_collision">
      <origin xyz="0 0 0" rpy="0 0 0"/>
      <geometry>
        <mesh filename="../custom_meshes/Right_Leg_Assembly_3_Nut_for_Screw_1.stl"/>
      </geometry>
    </collision>
    <inertial>
      <mass value="0"/>
      <inertia ixx="0" iyy="0" izz="0" ixy="0" ixz="0" iyz="0"/>
      <origin xyz="0 0 0.02876606" rpy="0 0 0"/>
    </inertial>
  </link>
  <link name="Right_Leg_Assembly_3_Screw_for_Nut_1">
    <visual name="Right_Leg_Assembly_3_Screw_for_Nut_1_visual">
      <origin xyz="0 0 0" rpy="0 0 0"/>
      <geometry>
        <mesh filename="../custom_meshes/Right_Leg_Assembly_3_Screw_for_Nut_1.stl"/>
      </geometry>
      <material name="Right_Leg_Assembly_3_Screw_for_Nut_1_material">
        <color rgba="0 0 0 1"/>
      </material>
    </visual>
    <collision name="Right_Leg_Assembly_3_Screw_for_Nut_1_collision">
      <origin xyz="0 0 0" rpy="0 0 0"/>
      <geometry>
        <mesh filename="../custom_meshes/Right_Leg_Assembly_3_Screw_for_Nut_1.stl"/>
      </geometry>
    </collision>
    <inertial>
      <mass value="0.05488579"/>
      <inertia ixx="0.00018843062" iyy="0.00018842875" izz="2.8454558e-06" ixy="-2.9131939e-09" ixz="4.291466e-08" iyz="1.2768433e-07"/>
      <origin xyz="1.0934975e-05 -2.6279199e-05 0.086328998" rpy="0 0 0"/>
    </inertial>
  </link>
  <link name="Right_Leg_Assembly_2_Nut_for_Screw_1">
    <visual name="Right_Leg_Assembly_2_Nut_for_Screw_1_visual">
      <origin xyz="0 0 0" rpy="0 0 0"/>
      <geometry>
        <mesh filename="../custom_meshes/Right_Leg_Assembly_2_Nut_for_Screw_1.stl"/>
      </geometry>
      <material name="Right_Leg_Assembly_2_Nut_for_Screw_1_material">
        <color rgba="0 0 1 1"/>
      </material>
    </visual>
    <collision name="Right_Leg_Assembly_2_Nut_for_Screw_1_collision">
      <origin xyz="0 0 0" rpy="0 0 0"/>
      <geometry>
        <mesh filename="../custom_meshes/Right_Leg_Assembly_2_Nut_for_Screw_1.stl"/>
      </geometry>
    </collision>
    <inertial>
      <mass value="0"/>
      <inertia ixx="0" iyy="0" izz="0" ixy="0" ixz="0" iyz="0"/>
      <origin xyz="0 0 0.02876606" rpy="0 0 0"/>
    </inertial>
  </link>
  <link name="Right_Leg_Assembly_2_Screw_for_Nut_1">
    <visual name="Right_Leg_Assembly_2_Screw_for_Nut_1_visual">
      <origin xyz="0 0 0" rpy="0 0 0"/>
      <geometry>
        <mesh filename="../custom_meshes/Right_Leg_Assembly_2_Screw_for_Nut_1.stl"/>
      </geometry>
      <material name="Right_Leg_Assembly_2_Screw_for_Nut_1_material">
        <color rgba="1 1 0 1"/>
      </material>
    </visual>
    <collision name="Right_Leg_Assembly_2_Screw_for_Nut_1_collision">
      <origin xyz="0 0 0" rpy="0 0 0"/>
      <geometry>
        <mesh filename="../custom_meshes/Right_Leg_Assembly_2_Screw_for_Nut_1.stl"/>
      </geometry>
    </collision>
    <inertial>
      <mass value="0.05488579"/>
      <inertia ixx="0.00018843062" iyy="0.00018842875" izz="2.8454558e-06" ixy="-2.9131939e-09" ixz="4.291466e-08" iyz="1.2768433e-07"/>
      <origin xyz="1.0934975e-05 -2.6279199e-05 0.086328998" rpy="0 0 0"/>
    </inertial>
  </link>
  <link name="Right_Leg_Assembly_1_Ball_Clamp_1">
    <visual name="Right_Leg_Assembly_1_Ball_Clamp_1_visual">
      <origin xyz="0 0 0" rpy="0 0 0"/>
      <geometry>
        <mesh filename="../custom_meshes/Right_Leg_Assembly_1_Ball_Clamp_1.stl"/>
      </geometry>
      <material name="Right_Leg_Assembly_1_Ball_Clamp_1_material">
        <color rgba="1 1 1 1"/>
      </material>
    </visual>
    <collision name="Right_Leg_Assembly_1_Ball_Clamp_1_collision">
      <origin xyz="0 0 0" rpy="0 0 0"/>
      <geometry>
        <mesh filename="../custom_meshes/Right_Leg_Assembly_1_Ball_Clamp_1.stl"/>
      </geometry>
    </collision>
    <inertial>
      <mass value="0"/>
      <inertia ixx="0" iyy="0" izz="0" ixy="0" ixz="0" iyz="0"/>
      <origin xyz="0 0 -0.03996976" rpy="0 0 0"/>
    </inertial>
  </link>
  <link name="Right_Leg_Assembly_4_Ball_Clamp_1">
    <visual name="Right_Leg_Assembly_4_Ball_Clamp_1_visual">
      <origin xyz="0 0 0" rpy="0 0 0"/>
      <geometry>
        <mesh filename="../custom_meshes/Right_Leg_Assembly_4_Ball_Clamp_1.stl"/>
      </geometry>
      <material name="Right_Leg_Assembly_4_Ball_Clamp_1_material">
        <color rgba="1 1 0 1"/>
      </material>
    </visual>
    <collision name="Right_Leg_Assembly_4_Ball_Clamp_1_collision">
      <origin xyz="0 0 0" rpy="0 0 0"/>
      <geometry>
        <mesh filename="../custom_meshes/Right_Leg_Assembly_4_Ball_Clamp_1.stl"/>
      </geometry>
    </collision>
    <inertial>
      <mass value="0"/>
      <inertia ixx="0" iyy="0" izz="0" ixy="0" ixz="0" iyz="0"/>
      <origin xyz="0 0 -0.03996976" rpy="0 0 0"/>
    </inertial>
  </link>
  <link name="Right_Leg_Assembly_3_Ball_Clamp_1">
    <visual name="Right_Leg_Assembly_3_Ball_Clamp_1_visual">
      <origin xyz="0 0 0" rpy="0 0 0"/>
      <geometry>
        <mesh filename="../custom_meshes/Right_Leg_Assembly_3_Ball_Clamp_1.stl"/>
      </geometry>
      <material name="Right_Leg_Assembly_3_Ball_Clamp_1_material">
        <color rgba="1 1 0 1"/>
      </material>
    </visual>
    <collision name="Right_Leg_Assembly_3_Ball_Clamp_1_collision">
      <origin xyz="0 0 0" rpy="0 0 0"/>
      <geometry>
        <mesh filename="../custom_meshes/Right_Leg_Assembly_3_Ball_Clamp_1.stl"/>
      </geometry>
    </collision>
    <inertial>
      <mass value="0"/>
      <inertia ixx="0" iyy="0" izz="0" ixy="0" ixz="0" iyz="0"/>
      <origin xyz="0 0 -0.03996976" rpy="0 0 0"/>
    </inertial>
  </link>
  <link name="Right_Leg_Assembly_2_Ball_Clamp_1">
    <visual name="Right_Leg_Assembly_2_Ball_Clamp_1_visual">
      <origin xyz="0 0 0" rpy="0 0 0"/>
      <geometry>
        <mesh filename="../custom_meshes/Right_Leg_Assembly_2_Ball_Clamp_1.stl"/>
      </geometry>
      <material name="Right_Leg_Assembly_2_Ball_Clamp_1_material">
        <color rgba="1 0 0 1"/>
      </material>
    </visual>
    <collision name="Right_Leg_Assembly_2_Ball_Clamp_1_collision">
      <origin xyz="0 0 0" rpy="0 0 0"/>
      <geometry>
        <mesh filename="../custom_meshes/Right_Leg_Assembly_2_Ball_Clamp_1.stl"/>
      </geometry>
    </collision>
    <inertial>
      <mass value="0"/>
      <inertia ixx="0" iyy="0" izz="0" ixy="0" ixz="0" iyz="0"/>
      <origin xyz="0 0 -0.03996976" rpy="0 0 0"/>
    </inertial>
  </link>
  <joint name="Front_Right_Mount_To_Body" type="fixed">
    <origin xyz="0.227029 0.07776784 -0.6147399" rpy="1.5707963 0 1.5707963"/>
    <parent link="Main_body_Frame_1"/>
    <child link="Front_Right_Side_Motor_Cap_1"/>
  </joint>
  <joint name="Front_Left_Motor_Mount_to" type="fixed">
    <origin xyz="-0.112971 0.07776784 -0.6147399" rpy="-1.5707963 0 1.5707963"/>
    <parent link="Main_body_Frame_1"/>
    <child link="Front_Left_Side_Motor_Cap_1"/>
  </joint>
  <joint name="Back_Left_Motor_Mount_to_Body" type="fixed">
    <origin xyz="-0.112971 0.65776784 -0.6147399" rpy="1.5707963 0 1.5707963"/>
    <parent link="Main_body_Frame_1"/>
    <child link="Back_Left_Motor_Cap_1"/>
  </joint>
  <joint name="Back_Right_Motor_Mount_to_Body" type="fixed">
    <origin xyz="0.227029 0.65776784 -0.6147399" rpy="1.5707963 0 1.5707963"/>
    <parent link="Main_body_Frame_1"/>
    <child link="Back_Right_Motor_Cap_1"/>
  </joint>
  <joint name="Front_Right_Motor_to_Mount" type="fixed">
    <origin xyz="0 0 0" rpy="3.1415927 0 -1.5707963"/>
    <parent link="Front_Right_Side_Motor_Cap_1"/>
    <child link="AK40_36_KV80_A_1"/>
  </joint>
  <joint name="Front_Left_Motor_to_Mount" type="fixed">
    <origin xyz="0 0 0" rpy="0 0 0"/>
    <parent link="Front_Left_Side_Motor_Cap_1"/>
    <child link="AK40_36_KV80_A_2"/>
  </joint>
  <joint name="Back_Left_Motor_to_Mount" type="fixed">
    <origin xyz="0 0 0" rpy="3.1415927 0 0"/>
    <parent link="Back_Left_Motor_Cap_1"/>
    <child link="AK40_36_KV80_A_3"/>
  </joint>
  <joint name="Back_right_motor_to_Mount" type="fixed">
    <origin xyz="0 0 0" rpy="0 0 0"/>
    <parent link="Back_Right_Motor_Cap_1"/>
    <child link="AK40_36_KV80_A_4"/>
  </joint>
  <joint name="Front_Right_Leg_to_Motor" type="revolute">
    <origin xyz="0 0 -0.052" rpy="0 0 -1.5707963"/>
    <parent link="AK40_36_KV80_A_1"/>
    <child link="Right_Leg_Assembly_1_Outer_thigh_1"/>
    <axis xyz="0 0 -1"/>
    <limit effort="1" velocity="1" lower="-6.2831853" upper="6.2831853"/>
  </joint>
  <joint name="Front_Left_Leg_to_Motor_Revolve" type="revolute">
    <origin xyz="-0.0008379 0.00022488 0.052" rpy="3.1415927 0 0"/>
    <parent link="AK40_36_KV80_A_2"/>
    <child link="Right_Leg_Assembly_4_Outer_thigh_1"/>
    <axis xyz="0 0 -1"/>
    <limit effort="1" velocity="1" lower="-6.2831853" upper="6.2831853"/>
  </joint>
  <joint name="Back_Left_Leg_Revolve" type="revolute">
    <origin xyz="0 0 0.052" rpy="0 0 -1.5707963"/>
    <parent link="AK40_36_KV80_A_3"/>
    <child link="Right_Leg_Assembly_3_Outer_thigh_1"/>
    <axis xyz="0 0 -1"/>
    <limit effort="1" velocity="1" lower="-6.2831853" upper="6.2831853"/>
  </joint>
  <joint name="Back_Right_Leg_to_Motor_Revolve" type="revolute">
    <origin xyz="0 0 0.052" rpy="0 0 1.5707963"/>
    <parent link="AK40_36_KV80_A_4"/>
    <child link="Right_Leg_Assembly_2_Outer_thigh_1"/>
    <axis xyz="0 0 -1"/>
    <limit effort="1" velocity="1" lower="-6.2831853" upper="6.2831853"/>
  </joint>
  <joint name="Pivot_Mate" type="revolute">
    <origin xyz="-0.03164705 0.38749781 -0.11437531" rpy="3.1415927 0 0"/>
    <parent link="Right_Leg_Assembly_1_Outer_thigh_1"/>
    <child link="Right_Leg_Assembly_1_Pivot_Pin_1"/>
    <axis xyz="0 0 -1"/>
    <limit effort="1" velocity="1" lower="-6.2831853" upper="6.2831853"/>
  </joint>
  <joint name="Fastened_5" type="fixed">
    <origin xyz="0 -0.053825 0" rpy="0 0 0"/>
    <parent link="Right_Leg_Assembly_1_Outer_thigh_1"/>
    <child link="Right_Leg_Assembly_1_Top_of_Leg_1"/>
  </joint>
  <joint name="Pivot_Mate-1" type="revolute">
    <origin xyz="-0.03164705 -0.38749781 -0.03437531" rpy="0 0 0"/>
    <parent link="Right_Leg_Assembly_4_Outer_thigh_1"/>
    <child link="Right_Leg_Assembly_4_Pivot_Pin_1"/>
    <axis xyz="0 0 -1"/>
    <limit effort="1" velocity="1" lower="-6.2831853" upper="6.2831853"/>
  </joint>
  <joint name="Fastened_5-1" type="fixed">
    <origin xyz="0 0.053825 -0.14875062" rpy="3.1415927 0 0"/>
    <parent link="Right_Leg_Assembly_4_Outer_thigh_1"/>
    <child link="Right_Leg_Assembly_4_Top_of_Leg_1"/>
  </joint>
  <joint name="Pivot_Mate-2" type="revolute">
    <origin xyz="-0.38749781 -0.03164705 0.03437531" rpy="3.1415927 0 1.5707963"/>
    <parent link="Right_Leg_Assembly_3_Outer_thigh_1"/>
    <child link="Right_Leg_Assembly_3_Pivot_Pin_1"/>
    <axis xyz="0 0 -1"/>
    <limit effort="1" velocity="1" lower="-6.2831853" upper="6.2831853"/>
  </joint>
  <joint name="Fastened_5-2" type="fixed">
    <origin xyz="0.053825 0 0.14875062" rpy="0 0 1.5707963"/>
    <parent link="Right_Leg_Assembly_3_Outer_thigh_1"/>
    <child link="Right_Leg_Assembly_3_Top_of_Leg_1"/>
  </joint>
  <joint name="Pivot_Mate-3" type="revolute">
    <origin xyz="-0.38749781 0.03164705 0.11437531" rpy="0 0 -1.5707963"/>
    <parent link="Right_Leg_Assembly_2_Outer_thigh_1"/>
    <child link="Right_Leg_Assembly_2_Pivot_Pin_1"/>
    <axis xyz="0 0 -1"/>
    <limit effort="1" velocity="1" lower="-6.2831853" upper="6.2831853"/>
  </joint>
  <joint name="Fastened_5-3" type="fixed">
    <origin xyz="0.053825 0 0" rpy="3.1415927 0 -1.5707963"/>
    <parent link="Right_Leg_Assembly_2_Outer_thigh_1"/>
    <child link="Right_Leg_Assembly_2_Top_of_Leg_1"/>
  </joint>
  <joint name="Fastened_2" type="fixed">
    <origin xyz="0 0 -0.04025" rpy="0 0 0"/>
    <parent link="Right_Leg_Assembly_1_Pivot_Pin_1"/>
    <child link="Right_Leg_Assembly_1_Shin_1"/>
  </joint>
  <joint name="Keep_Motor_Mount_Pin_in_place" type="dummy">
    <origin xyz="0 0.0075 -0.042375" rpy="0 0 0"/>
    <parent link="Right_Leg_Assembly_1_Top_of_Leg_1"/>
    <child link="Right_Leg_Assembly_1_Motor_Hinge_Pin_1"/>
  </joint>
  <joint name="Fastened_2-1" type="fixed">
    <origin xyz="0 0 -0.04025" rpy="0 0 0"/>
    <parent link="Right_Leg_Assembly_4_Pivot_Pin_1"/>
    <child link="Right_Leg_Assembly_4_Shin_1"/>
  </joint>
  <joint name="Keep_Motor_Mount_Pin_in_place-1" type="dummy">
    <origin xyz="0 0.0075 -0.042375" rpy="0 0 0"/>
    <parent link="Right_Leg_Assembly_4_Top_of_Leg_1"/>
    <child link="Right_Leg_Assembly_4_Motor_Hinge_Pin_1"/>
  </joint>
  <joint name="Fastened_2-2" type="fixed">
    <origin xyz="0 0 -0.04025" rpy="0 0 0"/>
    <parent link="Right_Leg_Assembly_3_Pivot_Pin_1"/>
    <child link="Right_Leg_Assembly_3_Shin_1"/>
  </joint>
  <joint name="Keep_Motor_Mount_Pin_in_place-2" type="dummy">
    <origin xyz="0 0.0075 -0.042375" rpy="0 0 0"/>
    <parent link="Right_Leg_Assembly_3_Top_of_Leg_1"/>
    <child link="Right_Leg_Assembly_3_Motor_Hinge_Pin_1"/>
  </joint>
  <joint name="Fastened_2-3" type="fixed">
    <origin xyz="0 0 -0.04025" rpy="0 0 0"/>
    <parent link="Right_Leg_Assembly_2_Pivot_Pin_1"/>
    <child link="Right_Leg_Assembly_2_Shin_1"/>
  </joint>
  <joint name="Keep_Motor_Mount_Pin_in_place-3" type="dummy">
    <origin xyz="0 0.0075 -0.042375" rpy="0 0 0"/>
    <parent link="Right_Leg_Assembly_2_Top_of_Leg_1"/>
    <child link="Right_Leg_Assembly_2_Motor_Hinge_Pin_1"/>
  </joint>
  <joint name="Fastened_3" type="fixed">
    <origin xyz="0.03164705 0.00326759 0" rpy="3.1415927 0 0"/>
    <parent link="Right_Leg_Assembly_1_Shin_1"/>
    <child link="Right_Leg_Assembly_1_Non_Pivot_Pin_1"/>
  </joint>
  <joint name="Fastened_4" type="fixed">
    <origin xyz="-0.18294605 0.00366571 0" rpy="3.1415927 -1.5707963 0"/>
    <parent link="Right_Leg_Assembly_1_Shin_1"/>
    <child link="Right_Leg_Assembly_1_Feet_1"/>
  </joint>
  <joint name="Combine_Motor_Pin_and_Hinge" type="prismatic">
    <origin xyz="0 0 -0.032" rpy="0 0 0"/>
    <parent link="Right_Leg_Assembly_1_Motor_Hinge_Pin_1"/>
    <child link="Right_Leg_Assembly_1_Motor_Hinge_1"/>
    <axis xyz="0 0 -1"/>
    <limit effort="1" velocity="1" lower="-0.1" upper="0.1"/>
  </joint>
  <joint name="Fastened_3-1" type="fixed">
    <origin xyz="0.03164705 0.00326759 0" rpy="3.1415927 0 0"/>
    <parent link="Right_Leg_Assembly_4_Shin_1"/>
    <child link="Right_Leg_Assembly_4_Non_Pivot_Pin_1"/>
  </joint>
  <joint name="Fastened_4-1" type="fixed">
    <origin xyz="-0.18294605 0.00366571 0" rpy="3.1415927 -1.5707963 0"/>
    <parent link="Right_Leg_Assembly_4_Shin_1"/>
    <child link="Right_Leg_Assembly_4_Feet_1"/>
  </joint>
  <joint name="Combine_Motor_Pin_and_Hinge-1" type="prismatic">
    <origin xyz="0 0 -0.032" rpy="0 0 0"/>
    <parent link="Right_Leg_Assembly_4_Motor_Hinge_Pin_1"/>
    <child link="Right_Leg_Assembly_4_Motor_Hinge_1"/>
    <axis xyz="0 0 -1"/>
    <limit effort="1" velocity="1" lower="-0.1" upper="0.1"/>
  </joint>
  <joint name="Fastened_3-2" type="fixed">
    <origin xyz="0.03164705 0.00326759 0" rpy="3.1415927 0 0"/>
    <parent link="Right_Leg_Assembly_3_Shin_1"/>
    <child link="Right_Leg_Assembly_3_Non_Pivot_Pin_1"/>
  </joint>
  <joint name="Fastened_4-2" type="fixed">
    <origin xyz="-0.18294605 0.00366571 0" rpy="3.1415927 -1.5707963 0"/>
    <parent link="Right_Leg_Assembly_3_Shin_1"/>
    <child link="Right_Leg_Assembly_3_Feet_1"/>
  </joint>
  <joint name="Combine_Motor_Pin_and_Hinge-2" type="prismatic">
    <origin xyz="0 0 -0.032" rpy="0 0 0"/>
    <parent link="Right_Leg_Assembly_3_Motor_Hinge_Pin_1"/>
    <child link="Right_Leg_Assembly_3_Motor_Hinge_1"/>
    <axis xyz="0 0 -1"/>
    <limit effort="1" velocity="1" lower="-0.1" upper="0.1"/>
  </joint>
  <joint name="Fastened_3-3" type="fixed">
    <origin xyz="0.03164705 0.00326759 0" rpy="3.1415927 0 0"/>
    <parent link="Right_Leg_Assembly_2_Shin_1"/>
    <child link="Right_Leg_Assembly_2_Non_Pivot_Pin_1"/>
  </joint>
  <joint name="Fastened_4-3" type="fixed">
    <origin xyz="-0.18294605 0.00366571 0" rpy="3.1415927 -1.5707963 0"/>
    <parent link="Right_Leg_Assembly_2_Shin_1"/>
    <child link="Right_Leg_Assembly_2_Feet_1"/>
  </joint>
  <joint name="Combine_Motor_Pin_and_Hinge-3" type="prismatic">
    <origin xyz="0 0 -0.032" rpy="0 0 0"/>
    <parent link="Right_Leg_Assembly_2_Motor_Hinge_Pin_1"/>
    <child link="Right_Leg_Assembly_2_Motor_Hinge_1"/>
    <axis xyz="0 0 -1"/>
    <limit effort="1" velocity="1" lower="-0.1" upper="0.1"/>
  </joint>
  <joint name="Revolute_1" type="revolute">
    <origin xyz="0 0 0.02195" rpy="0 0 0"/>
    <parent link="Right_Leg_Assembly_1_Non_Pivot_Pin_1"/>
    <child link="Right_Leg_Assembly_1_Connector_Screw_to_Shin_1"/>
    <axis xyz="0 0 -1"/>
    <limit effort="1" velocity="1" lower="-6.2831853" upper="6.2831853"/>
  </joint>
  <joint name="Fastened_1" type="fixed">
    <origin xyz="0 0.00594139 0" rpy="1.5707963 1.5707963 0"/>
    <parent link="Right_Leg_Assembly_1_Motor_Hinge_1"/>
    <child link="Right_Leg_Assembly_1_AK40_36_KV80_A_1"/>
  </joint>
  <joint name="Revolute_1-1" type="revolute">
    <origin xyz="0 0 0.02195" rpy="0 0 0"/>
    <parent link="Right_Leg_Assembly_4_Non_Pivot_Pin_1"/>
    <child link="Right_Leg_Assembly_4_Connector_Screw_to_Shin_1"/>
    <axis xyz="0 0 -1"/>
    <limit effort="1" velocity="1" lower="-6.2831853" upper="6.2831853"/>
  </joint>
  <joint name="Fastened_1-1" type="fixed">
    <origin xyz="0 0.00594139 0" rpy="1.5707963 1.5707963 0"/>
    <parent link="Right_Leg_Assembly_4_Motor_Hinge_1"/>
    <child link="Right_Leg_Assembly_4_AK40_36_KV80_A_1"/>
  </joint>
  <joint name="Revolute_1-2" type="revolute">
    <origin xyz="0 0 0.02195" rpy="0 0 0"/>
    <parent link="Right_Leg_Assembly_3_Non_Pivot_Pin_1"/>
    <child link="Right_Leg_Assembly_3_Connector_Screw_to_Shin_1"/>
    <axis xyz="0 0 -1"/>
    <limit effort="1" velocity="1" lower="-6.2831853" upper="6.2831853"/>
  </joint>
  <joint name="Fastened_1-2" type="fixed">
    <origin xyz="0 0.00594139 0" rpy="1.5707963 1.5707963 0"/>
    <parent link="Right_Leg_Assembly_3_Motor_Hinge_1"/>
    <child link="Right_Leg_Assembly_3_AK40_36_KV80_A_1"/>
  </joint>
  <joint name="Revolute_1-3" type="revolute">
    <origin xyz="0 0 0.02195" rpy="0 0 0"/>
    <parent link="Right_Leg_Assembly_2_Non_Pivot_Pin_1"/>
    <child link="Right_Leg_Assembly_2_Connector_Screw_to_Shin_1"/>
    <axis xyz="0 0 -1"/>
    <limit effort="1" velocity="1" lower="-6.2831853" upper="6.2831853"/>
  </joint>
  <joint name="Fastened_1-3" type="fixed">
    <origin xyz="0 0.00594139 0" rpy="1.5707963 1.5707963 0"/>
    <parent link="Right_Leg_Assembly_2_Motor_Hinge_1"/>
    <child link="Right_Leg_Assembly_2_AK40_36_KV80_A_1"/>
  </joint>
  <joint name="Connect_nut_to_connector" type="fixed">
    <origin xyz="0 0.26697128 -0.0215" rpy="1.5707963 -1.5707963 0"/>
    <parent link="Right_Leg_Assembly_1_Connector_Screw_to_Shin_1"/>
    <child link="Right_Leg_Assembly_1_Nut_for_Screw_1"/>
  </joint>
  <joint name="Fasten_motor_to_screw" type="fixed">
    <origin xyz="0 0 -0.052" rpy="3.1415927 0 0"/>
    <parent link="Right_Leg_Assembly_1_AK40_36_KV80_A_1"/>
    <child link="Right_Leg_Assembly_1_Screw_for_Nut_1"/>
  </joint>
  <joint name="Connect_nut_to_connector-1" type="fixed">
    <origin xyz="0 0.26697128 -0.0215" rpy="1.5707963 -1.5707963 0"/>
    <parent link="Right_Leg_Assembly_4_Connector_Screw_to_Shin_1"/>
    <child link="Right_Leg_Assembly_4_Nut_for_Screw_1"/>
  </joint>
  <joint name="Fasten_motor_to_screw-1" type="fixed">
    <origin xyz="0 0 -0.052" rpy="3.1415927 0 0"/>
    <parent link="Right_Leg_Assembly_4_AK40_36_KV80_A_1"/>
    <child link="Right_Leg_Assembly_4_Screw_for_Nut_1"/>
  </joint>
  <joint name="Connect_nut_to_connector-2" type="fixed">
    <origin xyz="0 0.26697128 -0.0215" rpy="1.5707963 -1.5707963 0"/>
    <parent link="Right_Leg_Assembly_3_Connector_Screw_to_Shin_1"/>
    <child link="Right_Leg_Assembly_3_Nut_for_Screw_1"/>
  </joint>
  <joint name="Fasten_motor_to_screw-2" type="fixed">
    <origin xyz="0 0 -0.052" rpy="3.1415927 0 0"/>
    <parent link="Right_Leg_Assembly_3_AK40_36_KV80_A_1"/>
    <child link="Right_Leg_Assembly_3_Screw_for_Nut_1"/>
  </joint>
  <joint name="Connect_nut_to_connector-3" type="fixed">
    <origin xyz="0 0.26697128 -0.0215" rpy="1.5707963 -1.5707963 0"/>
    <parent link="Right_Leg_Assembly_2_Connector_Screw_to_Shin_1"/>
    <child link="Right_Leg_Assembly_2_Nut_for_Screw_1"/>
  </joint>
  <joint name="Fasten_motor_to_screw-3" type="fixed">
    <origin xyz="0 0 -0.052" rpy="3.1415927 0 0"/>
    <parent link="Right_Leg_Assembly_2_AK40_36_KV80_A_1"/>
    <child link="Right_Leg_Assembly_2_Screw_for_Nut_1"/>
  </joint>
  <joint name="Revolute_2" type="revolute">
    <origin xyz="0 0 -0.0112037" rpy="3.1415927 0 0"/>
    <parent link="Right_Leg_Assembly_1_Nut_for_Screw_1"/>
    <child link="Right_Leg_Assembly_1_Ball_Clamp_1"/>
    <axis xyz="0 0 -1"/>
    <limit effort="1" velocity="1" lower="-6.2831853" upper="6.2831853"/>
  </joint>
  <joint name="Screw_to_Nut_Mate" type="prismatic">
    <origin xyz="0 0 -0.0112037" rpy="3.1415927 0 3.1415927"/>
    <parent link="Right_Leg_Assembly_1_Nut_for_Screw_1"/>
    <child link="Right_Leg_Assembly_1_Screw_for_Nut_1"/>
    <axis xyz="0 0 -1"/>
    <limit effort="1" velocity="1" lower="-0" upper="-0"/>
  </joint>
  <joint name="Revolute_2-1" type="revolute">
    <origin xyz="0 0 -0.0112037" rpy="3.1415927 0 0"/>
    <parent link="Right_Leg_Assembly_4_Nut_for_Screw_1"/>
    <child link="Right_Leg_Assembly_4_Ball_Clamp_1"/>
    <axis xyz="0 0 -1"/>
    <limit effort="1" velocity="1" lower="-6.2831853" upper="6.2831853"/>
  </joint>
  <joint name="Screw_to_Nut_Mate-1" type="prismatic">
    <origin xyz="0 0 -0.0112037" rpy="3.1415927 0 3.1415927"/>
    <parent link="Right_Leg_Assembly_4_Nut_for_Screw_1"/>
    <child link="Right_Leg_Assembly_4_Screw_for_Nut_1"/>
    <axis xyz="0 0 -1"/>
    <limit effort="1" velocity="1" lower="-0" upper="-0"/>
  </joint>
  <joint name="Revolute_2-2" type="revolute">
    <origin xyz="0 0 -0.0112037" rpy="3.1415927 0 0"/>
    <parent link="Right_Leg_Assembly_3_Nut_for_Screw_1"/>
    <child link="Right_Leg_Assembly_3_Ball_Clamp_1"/>
    <axis xyz="0 0 -1"/>
    <limit effort="1" velocity="1" lower="-6.2831853" upper="6.2831853"/>
  </joint>
  <joint name="Screw_to_Nut_Mate-2" type="prismatic">
    <origin xyz="0 0 -0.0112037" rpy="3.1415927 0 3.1415927"/>
    <parent link="Right_Leg_Assembly_3_Nut_for_Screw_1"/>
    <child link="Right_Leg_Assembly_3_Screw_for_Nut_1"/>
    <axis xyz="0 0 -1"/>
    <limit effort="1" velocity="1" lower="-0" upper="-0"/>
  </joint>
  <joint name="Revolute_2-3" type="revolute">
    <origin xyz="0 0 -0.0112037" rpy="3.1415927 0 0"/>
    <parent link="Right_Leg_Assembly_2_Nut_for_Screw_1"/>
    <child link="Right_Leg_Assembly_2_Ball_Clamp_1"/>
    <axis xyz="0 0 -1"/>
    <limit effort="1" velocity="1" lower="-6.2831853" upper="6.2831853"/>
  </joint>
  <joint name="Screw_to_Nut_Mate-3" type="prismatic">
    <origin xyz="0 0 -0.0112037" rpy="3.1415927 0 3.1415927"/>
    <parent link="Right_Leg_Assembly_2_Nut_for_Screw_1"/>
    <child link="Right_Leg_Assembly_2_Screw_for_Nut_1"/>
    <axis xyz="0 0 -1"/>
    <limit effort="1" velocity="1" lower="-0" upper="-0"/>
  </joint>
</robot>
